Workbook
Name Slicer_Annual_Report_Category: #N/A
Name Slicer_Annual_Report_Category1: #N/A
Name Slicer_Department: #N/A
Name Slicer_Department1: #N/A
Name Slicer_IPA_Rating_Clean: #N/A
Name Slicer_IPA_Rating_Clean1: #N/A
Name Slicer_Reporting_Year: #N/A

Sheet README
A1: UK Government Major Projects
A2: Cost, Schedule and Delivery-Risk Dashboard
A4: Portfolio analysis of the 2024–25 and 2025–26 NISTA Major Projects datasets
A6: This workbook analyses major UK government projects by department, whole-life cost, schedule duration and delivery-confidence rating. It combines multiple annual datasets through Power Query, models the portfolio in Power Pivot and applies a custom analytical risk score to support project-level prioritisation.
A12: Worksheet | B12: Purpose
A13: Executive Dashboard | B13: Headline portfolio KPIs and year comparison
A14: Departmental Analysis | B14: Department cost and delivery-risk comparison
A15: Project Risk Register | B15: Sortable project-level analytical risk register
A16: Risk Summary | B16: Risk-tier distribution and cost exposure
A17: Data Quality | B17: Record-count validation and data-completeness checks
A18: Methodology | B18: Data preparation, scoring rules and limitations
A19: README | B19: Workbook instructions and project overview
A21: Refresh instructions
A23: 1. Store the annual source CSV files in the designated source-data folder.
A24: 2. Do not manually edit the source CSV files.
A25: 3. Open the workbook and select Data → Refresh All.
A26: 4. Confirm the Data Quality page shows 213 records for 2024–25 and 189 records for 2025–26.
A27: 5. Check that dashboard slicers and PivotTables update successfully
A28: 6.Portfolio viewers can use the cached workbook outputs without the source CSV files; refreshing requires the annual source files in the established source-data folder.
A29: Technical features demonstrated
A31: 1.Power Query for importing, cleaning, standardising and appending annual datasets
A32: 2.Power Pivot relationships between fact and dimension tables
A33: 3.DAX measures for project counts, portfolio cost, duration and rating distribution
A34: 4.Custom 100-point analytical project-risk methodology
... A43: Workbook Details
A45: Item | B45: Value
A46: Author | B46: Wajedul Haque
A47: Tool | B47: Microsoft Excel 365
A48: Reporting years | B48: 2024–25 and 2025–26
A49: Source unit | B49: £ millions in 2024–25 real prices
A50: Data refresh | B50: Power Query
A51: Model | B51: Power Pivot and DAX
A52: Version | B52: 1

Sheet Executive Dashboard
A1: UK Government Major Projects Cost, Schedule and Delivery-Risk Dashboard
A6: Project Records | B6: Average Duration Months | C6: Red or Amber % of Rated Projects | D6: Total Whole Life Cost £bn
A7: 167 | B7: 148.92742 | C7: 0.93413174 | D7: 656.75249
A35: Portfolio reported at 31 March 2026 | Costs presented in 2024–25 real prices
A39: Analytical Risk Score is independently developed and is not an official government project rating.

Sheet Pivot Support
A1: Row Labels | B1: Project Records | F1: Row Labels | G1: Total Whole Life Cost £bn | J1: Project Name | K1: Total Risk Score | M1: Department | N1: GREEN | O1: AMBER | P1: RED
A2: AMBER | B2: 112 | F2: 2024-25 | G2: 336.58353 | J2: {=_xlfn.SORTBY( _xlfn._xlws.FILTER( CHOOSE({1,2}, 'Project Risk Register'!$A$2:$A$190, 'Project Risk Register'!$N$2:$N$190), 'Project Risk Register'!$N$2:$N$190<>""), _xlfn._xlws.FILTER('Project Risk Register'!$N$2:$N$190,'Project Risk Register'!$N$2:$N$190<>""),-1, _xlfn._xlws.FILTER('Project Risk Register'!$F$2:$F$190,'Project Risk Register'!$N$2:$N$190<>""),-1)} -> ARMOURED CAVALRY 2025 | K2: 100 | M2: ='Departmental Analysis'!A26 -> MOD | N2: =COUNTIFS( 'Project Risk Register'!$B$2:$B$190,$M2, 'Project Risk Register'!$I$2:$I$190,N$1) -> 1 | O2: =COUNTIFS( 'Project Risk Register'!$B$2:$B$190,$M2, 'Project Risk Register'!$I$2:$I$190,O$1) -> 10 | P2: =COUNTIFS( 'Project Risk Register'!$B$2:$B$190,$M2, 'Project Risk Register'!$I$2:$I$190,P$1) -> 9
A3: GREEN | B3: 11 | F3: 2025-26 | G3: 320.16896 | J3: ARMOUR MBT 2025 | K3: 95 | M3: ='Departmental Analysis'!A27 -> DFT | N3: =COUNTIFS( 'Project Risk Register'!$B$2:$B$190,$M3, 'Project Risk Register'!$I$2:$I$190,N$1) -> 0 | O3: =COUNTIFS( 'Project Risk Register'!$B$2:$B$190,$M3, 'Project Risk Register'!$I$2:$I$190,O$1) -> 3 | P3: =COUNTIFS( 'Project Risk Register'!$B$2:$B$190,$M3, 'Project Risk Register'!$I$2:$I$190,P$1) -> 3
A4: RED | B4: 44 | F4: Grand Total | G4: 656.75249 | J4: FARMING AND COUNTRYSIDE PROGRAMME | K4: 90 | M4: ='Departmental Analysis'!A28 -> HO | N4: =COUNTIFS( 'Project Risk Register'!$B$2:$B$190,$M4, 'Project Risk Register'!$I$2:$I$190,N$1) -> 0 | O4: =COUNTIFS( 'Project Risk Register'!$B$2:$B$190,$M4, 'Project Risk Register'!$I$2:$I$190,O$1) -> 6 | P4: =COUNTIFS( 'Project Risk Register'!$B$2:$B$190,$M4, 'Project Risk Register'!$I$2:$I$190,P$1) -> 2
J5: Remediation Portfolio | K5: 90 | M5: ='Departmental Analysis'!A29 -> DESNZ | N5: =COUNTIFS( 'Project Risk Register'!$B$2:$B$190,$M5, 'Project Risk Register'!$I$2:$I$190,N$1) -> 0 | O5: =COUNTIFS( 'Project Risk Register'!$B$2:$B$190,$M5, 'Project Risk Register'!$I$2:$I$190,O$1) -> 4 | P5: =COUNTIFS( 'Project Risk Register'!$B$2:$B$190,$M5, 'Project Risk Register'!$I$2:$I$190,P$1) -> 3
J6: EAST COAST DIGITAL PROGRAMME | K6: 90 | M6: ='Departmental Analysis'!A30 -> DHSC | N6: =COUNTIFS( 'Project Risk Register'!$B$2:$B$190,$M6, 'Project Risk Register'!$I$2:$I$190,N$1) -> 1 | O6: =COUNTIFS( 'Project Risk Register'!$B$2:$B$190,$M6, 'Project Risk Register'!$I$2:$I$190,O$1) -> 2 | P6: =COUNTIFS( 'Project Risk Register'!$B$2:$B$190,$M6, 'Project Risk Register'!$I$2:$I$190,P$1) -> 0
J7: SUBMARINE WATERFRONT INFRASTRUCTURE FUTURE | K7: 90 | M7: ='Departmental Analysis'!A31 -> DEFRA | N7: =COUNTIFS( 'Project Risk Register'!$B$2:$B$190,$M7, 'Project Risk Register'!$I$2:$I$190,N$1) -> 2 | O7: =COUNTIFS( 'Project Risk Register'!$B$2:$B$190,$M7, 'Project Risk Register'!$I$2:$I$190,O$1) -> 4 | P7: =COUNTIFS( 'Project Risk Register'!$B$2:$B$190,$M7, 'Project Risk Register'!$I$2:$I$190,P$1) -> 2
J8: NEW HOSPITAL PROGRAMME | K8: 85 | M8: ='Departmental Analysis'!A32 -> MHCLG | N8: =COUNTIFS( 'Project Risk Register'!$B$2:$B$190,$M8, 'Project Risk Register'!$I$2:$I$190,N$1) -> 0 | O8: =COUNTIFS( 'Project Risk Register'!$B$2:$B$190,$M8, 'Project Risk Register'!$I$2:$I$190,O$1) -> 2 | P8: =COUNTIFS( 'Project Risk Register'!$B$2:$B$190,$M8, 'Project Risk Register'!$I$2:$I$190,P$1) -> 1
J9: NORTHERN POWERHOUSE RAIL | K9: 85 | M9: ='Departmental Analysis'!A33 -> DFE | N9: =COUNTIFS( 'Project Risk Register'!$B$2:$B$190,$M9, 'Project Risk Register'!$I$2:$I$190,N$1) -> 1 | O9: =COUNTIFS( 'Project Risk Register'!$B$2:$B$190,$M9, 'Project Risk Register'!$I$2:$I$190,O$1) -> 0 | P9: =COUNTIFS( 'Project Risk Register'!$B$2:$B$190,$M9, 'Project Risk Register'!$I$2:$I$190,P$1) -> 0
J10: Hydrogen Allocation Round 2 (HAR2) | K10: 85 | M10: ='Departmental Analysis'!A34 -> DWP | N10: =COUNTIFS( 'Project Risk Register'!$B$2:$B$190,$M10, 'Project Risk Register'!$I$2:$I$190,N$1) -> 1 | O10: =COUNTIFS( 'Project Risk Register'!$B$2:$B$190,$M10, 'Project Risk Register'!$I$2:$I$190,O$1) -> 5 | P10: =COUNTIFS( 'Project Risk Register'!$B$2:$B$190,$M10, 'Project Risk Register'!$I$2:$I$190,P$1) -> 0
J11: LAND ENVIRONMENT TACTICAL COMMUNICATION AND INFORMATION SYSTEMS | K11: 85 | M11: ='Departmental Analysis'!A35 -> MOJ | N11: =COUNTIFS( 'Project Risk Register'!$B$2:$B$190,$M11, 'Project Risk Register'!$I$2:$I$190,N$1) -> 0 | O11: =COUNTIFS( 'Project Risk Register'!$B$2:$B$190,$M11, 'Project Risk Register'!$I$2:$I$190,O$1) -> 5 | P11: =COUNTIFS( 'Project Risk Register'!$B$2:$B$190,$M11, 'Project Risk Register'!$I$2:$I$190,P$1) -> 2
J12: MECHANISED INFANTRY PROGRAMME | K12: 85
J13: NEW STYLE OF INFORMATION TECHNOLOGY DEPLOYED | K13: 85
J14: GEOLOGICAL DISPOSAL FACILITY | K14: 80
J15: COLLECTIVE TRAINING TRANSFORMATION PROGRAMME | K15: 80
J16: LAND INTELLIGENCE, SURVEILLANCE, TARGET ACQUISITION AND RECONNAISSANCE (ISTAR) | K16: 80
J17: GROUND BASED AIR DEFENCE (GBAD) | K17: 80
J18: Law Enforcement Data Service | K18: 80
J19: CORE PRODUCTION CAPABILITY | K19: 75
J20: COLLECTIONS, PACKAGING AND REFORMS PROGRAMME | K20: 75
J21: FUTURE BORDER AND IMMIGRATION SYSTEM PROGRAMME (FBIS) | K21: 75
J22: SERVICE MODERNISATION PROGRAMME | K22: 75
J23: FUTURE AIR DOMINANCE SYSTEM | K23: 75
... J82: Mobile Fires Platform | K82: 25

Sheet Departmental Analysis
A25: Department | B25: Total Whole Life Cost £m | C25: Red or Amber % | D25: Project Records | E25: Average Duration Months | G25: Department | H25: Total Whole Life Cost £m | J25: Reporting Year | K25: All
A26: MOD | B26: 195988.87 | C26: 0.95 | D26: 91 | E26: 232.56029 | G26: MOJ | H26: 31999.22
A27: DFT | B27: 139441.09 | C27: 1 | D27: 35 | E27: 197.12174 | G27: DWP | H27: 38425.49 | J27: Delivery Rating | K27: Project Records
A28: HO | B28: 135300.67 | C28: 1 | D28: 37 | E28: 89.705 | G28: DFE | H28: 44007.75 | J28: AMBER | K28: 112
A29: DESNZ | B29: 128438.29 | C29: 1 | D29: 40 | E29: 170.56538 | G29: MHCLG | H29: 69374.62 | J29: GREEN | K29: 11
A30: DHSC | B30: 115176.44 | C30: 0.83333333 | D30: 18 | E30: 123.43571 | G30: DEFRA | H30: 83749.57 | J30: RED | K30: 44
A31: DEFRA | B31: 83749.57 | C31: 0.875 | D31: 23 | E31: 107.52 | G31: DHSC | H31: 115176.44 | J31: Grand Total | K31: 167
A32: MHCLG | B32: 69374.62 | C32: 0.9 | D32: 21 | E32: 122.86154 | G32: DESNZ | H32: 128438.29
A33: DFE | B33: 44007.75 | D33: 18 | E33: 86.633333 | G33: HO | H33: 135300.67
A34: DWP | B34: 38425.49 | C34: 0.78571429 | D34: 15 | E34: 111.68 | G34: DFT | H34: 139441.09
A35: MOJ | B35: 31999.22 | C35: 0.93333333 | D35: 36 | E35: 82.286111 | G35: MOD | H35: 195988.87
A36: Grand Total | B36: 981902.01 | C36: 0.92361111 | D36: 334 | E36: 155.44274 | G36: Grand Total | H36: 981902.01

Sheet Project Risk Register
A1: Project Name | B1: Department | C1: Annual Report Category | D1: Major Projects ID | E1: Reporting Year | F1: Whole Life Cost Clean | G1: Duration Months | H1: FY Variance Clean | I1: IPA Rating Clean | J1: Delivery Risk Score | K1: Cost Exposure Score | L1: Duration Exposure Score | M1: Variance Risk Score | N1: Total Risk Score | O1: Risk Tier
A2: ARMOURED CAVALRY 2025 | B2: MOD | C2: Military Capability | D2: MOD_0091_1415-Q3 | E2: 2025-26 | F2: 8935.68 | G2: 183.8 | H2: 23.88 | I2: RED | J2: 40 | K2: 25 | L2: 20 | M2: 15 | N2: 100 | O2: Critical
A3: ARMOUR MBT 2025 | B3: MOD | C3: Military Capability | D3: MOD_0104_1617-Q1 | E3: 2025-26 | F3: 1979.22 | G3: 214.2 | H3: 33.29 | I3: RED | J3: 40 | K3: 20 | L3: 20 | M3: 15 | N3: 95 | O3: Critical
A4: FARMING AND COUNTRYSIDE PROGRAMME | B4: DEFRA | C4: Government Transformation and Service Delivery | D4: DEFRA_0008_2021-Q1 | E4: 2025-26 | F4: 25494.95 | G4: 140 | H4: 9.38 | I4: RED | J4: 40 | K4: 25 | L4: 20 | M4: 5 | N4: 90 | O4: Critical
A5: EAST COAST DIGITAL PROGRAMME | B5: DFT | C5: Infrastructure and Construction | D5: DFT_0038_1920-Q4 | E5: 2025-26 | F5: 3030.39 | G5: 161.4 | H5: 15.88 | I5: RED | J5: 40 | K5: 20 | L5: 20 | M5: 10 | N5: 90 | O5: Critical
A6: Remediation Portfolio | B6: MHCLG | C6: Infrastructure and Construction | D6: DLUHC_0250_2324-Q1 | E6: 2025-26 | F6: 9726.6 | G6: 153.2 | H6: 5.3 | I6: RED | J6: 40 | K6: 25 | L6: 20 | M6: 5 | N6: 90 | O6: Critical
A7: SUBMARINE WATERFRONT INFRASTRUCTURE FUTURE | B7: MOD | C7: Infrastructure and Construction | D7: MOD_0011_2122-Q2 | E7: 2025-26 | F7: 2230.52 | G7: 172.6 | H7: 17.7 | I7: RED | J7: 40 | K7: 20 | L7: 20 | M7: 10 | N7: 90 | O7: Critical
A8: Hydrogen Allocation Round 2 (HAR2) | B8: DESNZ | C8: Infrastructure and Construction | D8: DESNZ_0397_2425-Q2 | E8: 2025-26 | F8: 9427.02 | G8: 216.6 | I8: RED | J8: 40 | K8: 25 | L8: 20 | M8: 0 | N8: 85 | O8: Critical
A9: NORTHERN POWERHOUSE RAIL | B9: DFT | C9: Infrastructure and Construction | D9: DFT_0141_2223-Q1 | E9: 2025-26 | F9: 45000 | G9: 430.9 | H9: 69.79 | I9: AMBER | J9: 25 | K9: 25 | L9: 20 | M9: 15 | N9: 85 | O9: Critical
A10: NEW HOSPITAL PROGRAMME | B10: DHSC | C10: Infrastructure and Construction | D10: DHSC_0066_2021-Q2 | E10: 2025-26 | F10: 47523.91 | G10: 303.1 | H10: 24.01 | I10: AMBER | J10: 25 | K10: 25 | L10: 20 | M10: 15 | N10: 85 | O10: Critical
A11: LAND ENVIRONMENT TACTICAL COMMUNICATION AND INFORMATION SYSTEMS | B11: MOD | C11: Military Capability | D11: MOD_0105_1617-Q1 | E11: 2025-26 | F11: 7734.29 | G11: 266.5 | H11: 47.19 | I11: AMBER | J11: 25 | K11: 25 | L11: 20 | M11: 15 | N11: 85 | O11: Critical
A12: NEW STYLE OF INFORMATION TECHNOLOGY DEPLOYED | B12: MOD | C12: Information and Communications Technology (ICT) | D12: MOD_0109_1617-Q2 | E12: 2025-26 | F12: 1598.79 | G12: 168 | H12: 2.42 | I12: RED | J12: 40 | K12: 20 | L12: 20 | M12: 5 | N12: 85 | O12: Critical
A13: MECHANISED INFANTRY PROGRAMME | B13: MOD | C13: Military Capability | D13: MOD_0115_1718-Q2 | E13: 2025-26 | F13: 5033.66 | G13: 190.4 | H13: 54.27 | I13: AMBER | J13: 25 | K13: 25 | L13: 20 | M13: 15 | N13: 85 | O13: Critical
A14: GEOLOGICAL DISPOSAL FACILITY | B14: DESNZ | C14: Infrastructure and Construction | D14: DECC_0005_1112-Q1 | E14: 2025-26 | F14: 26350.29 | H14: 21.71 | I14: RED | J14: 40 | K14: 25 | L14: 0 | M14: 15 | N14: 80 | O14: Critical
A15: Law Enforcement Data Service | B15: HO | C15: Information and Communications Technology (ICT) | D15: HO_0036_1617-Q2 | E15: 2025-26 | F15: 1086.68 | G15: 153 | H15: 35.18 | I15: AMBER | J15: 25 | K15: 20 | L15: 20 | M15: 15 | N15: 80 | O15: Critical
A16: COLLECTIVE TRAINING TRANSFORMATION PROGRAMME | B16: MOD | C16: Military Capability | D16: MOD_0121_2021-Q4 | E16: 2025-26 | F16: 2083.25 | G16: 261.9 | H16: 23.24 | I16: AMBER | J16: 25 | K16: 20 | L16: 20 | M16: 15 | N16: 80 | O16: Critical
A17: LAND INTELLIGENCE, SURVEILLANCE, TARGET ACQUISITION AND RECONNAISSANCE (ISTAR) | B17: MOD | C17: Military Capability | D17: MOD_0056_2122-Q3 | E17: 2025-26 | F17: 1498.14 | G17: 171.2 | H17: 34.54 | I17: AMBER | J17: 25 | K17: 20 | L17: 20 | M17: 15 | N17: 80 | O17: Critical
A18: GROUND BASED AIR DEFENCE (GBAD) | B18: MOD | C18: Military Capability | D18: MOD_0144_2122-Q1 | E18: 2025-26 | F18: 1454.95 | G18: 186 | H18: 43.75 | I18: AMBER | J18: 25 | K18: 20 | L18: 20 | M18: 15 | N18: 80 | O18: Critical
A19: COLLECTIONS, PACKAGING AND REFORMS PROGRAMME | B19: DEFRA | C19: Government Transformation and Service Delivery | D19: DEFRA_0040_2122-Q3 | E19: 2025-26 | F19: 5204.73 | G19: 122 | H19: 3.24 | I19: AMBER | J19: 25 | K19: 25 | L19: 20 | M19: 5 | N19: 75 | O19: Critical
A20: SERVICE MODERNISATION PROGRAMME | B20: DWP | C20: Government Transformation and Service Delivery | D20: DWP_0217_2223-Q4 | E20: 2025-26 | F20: 1150 | G20: 132 | H20: 13.19 | I20: AMBER | J20: 25 | K20: 20 | L20: 20 | M20: 10 | N20: 75 | O20: Critical
A21: FUTURE BORDER AND IMMIGRATION SYSTEM PROGRAMME (FBIS) | B21: HO | C21: Government Transformation and Service Delivery | D21: HO_0039_1920-Q4 | E21: 2025-26 | F21: 5140.89 | G21: 108 | H21: 18.09 | I21: AMBER | J21: 25 | K21: 25 | L21: 15 | M21: 10 | N21: 75 | O21: Critical
A22: FUTURE AIR DOMINANCE SYSTEM | B22: MOD | C22: Military Capability | D22: MOD_0479_2425-Q4 | E22: 2025-26 | G22: 283 | H22: 30.71 | I22: RED | J22: 40 | K22: 0 | L22: 20 | M22: 15 | N22: 75 | O22: Critical
A23: CORE PRODUCTION CAPABILITY | B23: MOD | C23: Military Capability | D23: MOD_0078_1213-Q1 | E23: 2025-26 | F23: 7784.34 | G23: 380.2 | H23: 7.77 | I23: AMBER | J23: 25 | K23: 25 | L23: 20 | M23: 5 | N23: 75 | O23: Critical
A24: 10K Additional Prison Places Estate Expansion Houseblocks and Refurbishments | B24: MOJ | C24: Infrastructure and Construction | D24: MOJ_0113_2122-Q2 | E24: 2025-26 | G24: 137.7 | H24: 56.9 | I24: RED | J24: 40 | K24: 0 | L24: 20 | M24: 15 | N24: 75 | O24: Critical
A25: 10K Additional Prison Places Estate Expansion Category D | B25: MOJ | C25: Infrastructure and Construction | D25: MOJ_0111_2122-Q2 | E25: 2025-26 | G25: 133.8 | H25: 65.99 | I25: RED | J25: 40 | K25: 0 | L25: 20 | M25: 15 | N25: 75 | O25: Critical
A26: Warm Homes Agency | B26: DESNZ | C26: Government Transformation and Service Delivery | D26: DESNZ_0542_2526-Q2 | E26: 2025-26 | F26: 276.69 | G26: 41.8 | H26: 16.77 | I26: RED | J26: 40 | K26: 10 | L26: 10 | M26: 10 | N26: 70 | O26: Critical
A27: LOWER THAMES CROSSING | B27: DFT | C27: Infrastructure and Construction | D27: DFT_0022_1415-Q4 | E27: 2025-26 | F27: 9899.54 | G27: 254 | H27: 0 | I27: AMBER | J27: 25 | K27: 25 | L27: 20 | M27: 0 | N27: 70 | O27: Critical
A28: Health Transformation Programme | B28: DWP | C28: Government Transformation and Service Delivery | D28: DWP_0028_1819-Q3 | E28: 2025-26 | F28: 735.46 | G28: 138 | H28: 10.98 | I28: AMBER | J28: 25 | K28: 15 | L28: 20 | M28: 10 | N28: 70 | O28: Critical
A29: Workplace Transformation | B29: DWP | C29: Government Transformation and Service Delivery | D29: DWP_0013_2122-Q2 | E29: 2025-26 | F29: 3367.17 | G29: 128.9 | H29: 2.09 | I29: AMBER | J29: 25 | K29: 20 | L29: 20 | M29: 5 | N29: 70 | O29: Critical
A30: UNITY PROGRAMME | B30: HMRC | C30: Government Transformation and Service Delivery | D30: HMRC_0031_2122-Q3 | E30: 2025-26 | F30: 245.97 | G30: 86.9 | H30: 0.29 | I30: RED | J30: 40 | K30: 10 | L30: 15 | M30: 5 | N30: 70 | O30: Critical
A31: MAKING TAX DIGITAL | B31: HMRC | C31: Information and Communications Technology (ICT) | D31: HMRC_0017_1617-Q2 | E31: 2025-26 | F31: 1484.62 | G31: 155.9 | H31: 0.34 | I31: AMBER | J31: 25 | K31: 20 | L31: 20 | M31: 5 | N31: 70 | O31: Critical
A32: HOME OFFICE BIOMETRICS (HOB) PROGRAMME | B32: HO | C32: Information and Communications Technology (ICT) | D32: HO_0033_1415-Q3 | E32: 2025-26 | F32: 1809.85 | G32: 153 | H32: 2.74 | I32: AMBER | J32: 25 | K32: 20 | L32: 20 | M32: 5 | N32: 70 | O32: Critical
A33: CLYDE INFRASTRUCTURE | B33: MOD | C33: Military Capability | D33: MOD_0118_1718-Q3 | E33: 2025-26 | F33: 3324.98 | G33: 198.8 | H33: 7.43 | I33: AMBER | J33: 25 | K33: 20 | L33: 20 | M33: 5 | N33: 70 | O33: Critical
A34: SOCIAL HOUSING DECARBONISATION FUND | B34: DESNZ | C34: Infrastructure and Construction | D34: BEIS_0014_2021-Q4 | E34: 2025-26 | F34: 2256.29 | G34: 114.7 | H34: 0.12 | I34: AMBER | J34: 25 | K34: 20 | L34: 15 | M34: 5 | N34: 65 | O34: High
A35: FRONTLINE DIGITISATION | B35: DHSC | C35: Information and Communications Technology (ICT) | D35: DHSC_0071_2122-Q1 | E35: 2025-26 | F35: 2080.52 | G35: 60 | H35: 2.61 | I35: AMBER | J35: 25 | K35: 20 | L35: 15 | M35: 5 | N35: 65 | O35: High
A36: SYNERGY PROGRAMME | B36: DWP | C36: Government Transformation and Service Delivery | D36: DWP_0042_2122-Q3 | E36: 2025-26 | F36: 1990.99 | G36: 94 | H36: 5.21 | I36: AMBER | J36: 25 | K36: 20 | L36: 15 | M36: 5 | N36: 65 | O36: High
A37: EMERGENCY SERVICES MOBILE COMMUNICATIONS | B37: HO | C37: Information and Communications Technology (ICT) | D37: HO_0016_1213-Q1 | E37: 2025-26 | F37: 18139.58 | H37: 49.93 | I37: AMBER | J37: 25 | K37: 25 | L37: 0 | M37: 15 | N37: 65 | O37: High
A38: Affordable Homes Programme (AHP) | B38: MHCLG | C38: Infrastructure and Construction | D38: DLUHC_0138_2223-Q1 | E38: 2025-26 | F38: 12230.5 | G38: 110.8 | H38: 0 | I38: AMBER | J38: 25 | K38: 25 | L38: 15 | M38: 0 | N38: 65 | O38: High
A39: Electronic Monitoring Expansion | B39: MOJ | C39: Government Transformation and Service Delivery | D39: MOJ_0058_2122-Q1 | E39: 2025-26 | F39: 1161.1 | G39: 65.4 | H39: 6.34 | I39: AMBER | J39: 25 | K39: 20 | L39: 15 | M39: 5 | N39: 65 | O39: High
A40: Manchester Digital Campus | B40: CO | C40: Infrastructure and Construction | D40: CO_0438_2425-Q3 | E40: 2025-26 | F40: 1029.78 | G40: 92.3 | H40: 0 | I40: AMBER | J40: 25 | K40: 20 | L40: 15 | M40: 0 | N40: 60 | O40: High
...

Sheet Risk Summary
A1: Risk scoring combines delivery confidence, whole-life cost exposure, project duration and financial-year variance.
C32: Risk Tier | D32: Project Count | E32: Total Whole-Life Cost £m | F32: Average Risk Score | H32: Risk Tier | I32: Count of Project Name
C33: Critical | D33: 32 | E33: 240612.58 | F33: 79.6875 | H33: Critical | I33: 32
C34: High | D34: 30 | E34: 54761.72 | F34: 57.5 | H34: High | I34: 30
C35: Medium | D35: 16 | E35: 24794.66 | F35: 40.3125 | H35: Medium | I35: 16
C36: Low | D36: 3 | F36: 25 | H36: Low | I36: 3
C37: Not scored | D37: 108 | E37: 143883.7 | H37: Grand Total | I37: 81
C38: Grand Total | D38: 189 | E38: 464052.66 | F38: 61.666667

Sheet Data Quality
A1: Portfolio Validation
A3: Confirms record counts, rating distribution and whole-life cost totals after refresh.
A5: Reporting Year | B5: Count of Project Name | C5: Sum of Whole Life Cost Clean | E5: Reporting Year | F5: Project Records | G5: Missing Cost Projects | H5: Missing Duration Projects | I5: Unrated Projects | J5: Cost Data Coverage % | K5: Duration Data Coverage %
A6: 2024-25 | B6: 213 | C6: 565707.28 | E6: 2024-25 | F6: 213 | G6: 56 | H6: 59 | I6: 127 | J6: 0.7370892 | K6: 0.72300469
A7: AMBER | B7: 61 | C7: 213382.35 | E7: 2025-26 | F7: 189 | G7: 56 | H7: 57 | I7: 108 | J7: 0.7037037 | K7: 0.6984127
A8: GREEN | B8: 5 | C8: 20339.06 | E8: Grand Total | F8: 402 | G8: 112 | H8: 116 | I8: 235 | J8: 0.72139303 | K8: 0.71144279
A9: RED | B9: 20 | C9: 102862.12
A10: (blank) | B10: 127 | C10: 229123.75
A11: 2025-26 | B11: 189 | C11: 464052.66
A12: AMBER | B12: 51 | C12: 205226.67
A13: GREEN | B13: 6 | C13: 25120.67
A14: RED | B14: 24 | C14: 89821.62
A15: (blank) | B15: 108 | C15: 143883.7
A16: Grand Total | B16: 402 | C16: 1029759.9

Sheet Methodology
A1: Methodology and Assumptions
A5: UK Government Major Projects | Cost, Schedule and Delivery-Risk Dashboard
A8: 1. Purpose
A10: This workbook analyses UK Government Major Projects across the 2024–25 and 2025–26 reporting periods. It compares project cost, duration, departmental responsibility and delivery-confidence ratings, and applies a custom analytical risk score to support portfolio-level prioritisation.
A14: 2. Data Sources
A16: Item | B16: Description
A17: Source | B17: NISTA Major Projects Annual Report dataset
A18: Reporting Periods | B18: 2024–25 and 2025–26
A19: Grain | B19: One row per project per reporting period
A20: Cost unit | B20: £ millions, presented in 2024–25 real prices
A21: Refresh method | B21: Power Query
A22: Analytical model | B22: Excel Data Model and Power Pivot
A24: Original text fields are retained where the source contains exemptions, planning-stage notes or ranges. Separate cleaned numeric and date fields are used for analysis.
A27: 3. Data Preparation Rules
A29: Field | B29: Cleaning rule
A30: Department | B30: Trimmed, cleaned and standardised to uppercase for relationships
A31: Reporting Year | B31: Added during Power Query import
A32: Start Date | B32: Valid UK-format dates converted; other text becomes null
A33: End Date | B33: Valid UK-format dates converted; ranges may remain unavailable
A34: Duration Months | B34: Days between clean start and end dates divided by 30.44
A35: Whole-Life Cost | B35: Numeric values retained; midpoint used for Low/Mid/High ranges
A36: Benefits | B36: Numeric values retained; midpoint used where a range is supplied
A37: IPA Rating | B37: Standardised to RED, AMBER or GREEN
A38: Missing/exempt values | B38: Retained in original fields and represented as null analytically
A40: 4. Analytical Risk Score
A42: The risk score is an independently developed analytical indicator. It is not an official NISTA or departmental project rating.
A44: Component | B44: Rule | C44: Points
A45: Delivery confidence | B45: Green | C45: 5
B46: Amber | C46: 25
B47: Red | C47: 40
A48: Cost exposure | B48: Under £100m | C48: 5
B49: £100m–£500m | C49: 10
B50: £500m–£1bn | C50: 15
B51: £1bn–£5bn | C51: 20
B52: £5bn+ | C52: 25
A53: Duration exposure | B53: Under 3 years | C53: 5
B54: 3–5 years | C54: 10
B55: 5–10 years | C55: 15
B56: 10+ years | C56: 20
A57: Financial variance | B57: 0% or lower | C57: 0
...
